Workbook

Sheet PARTICIPANTES
A1: Gestor | B1: Razão Social | C1: CNPJ | D1: Conta | E1: Tipo conta | F1: Quantidade | G1: % | H1: Presença (OK ou Fora) | I1: Representante | J1: Voto 1 | K1: Voto 2 | L1: Voto 3
G2: =IF(OR(MID(D2,7,2)="10",MID(D2,7,2)="20",MID(D2,7,2)="68"),SUMIF(COMITENTES!#REF!,D2,COMITENTES!$H:$H),IF(H2="fora",0%,F2/QUÓRUM!$H$4)) -> #DIV/0! | H2: =IF(OR(MID(D2,7,2)="10",MID(D2,7,2)="20",MID(D2,7,2)="68"),"PREENCHER NA PRÓXIMA ABA","")
G3: =IF(OR(MID(D3,7,2)="10",MID(D3,7,2)="20",MID(D3,7,2)="68"),SUMIF(COMITENTES!#REF!,D3,COMITENTES!$H:$H),IF(H3="fora",0%,F3/QUÓRUM!$H$4)) -> #DIV/0! | H3: =IF(OR(MID(D3,7,2)="10",MID(D3,7,2)="20",MID(D3,7,2)="68"),"PREENCHER NA PRÓXIMA ABA","")
G4: =IF(OR(MID(D4,7,2)="10",MID(D4,7,2)="20",MID(D4,7,2)="68"),SUMIF(COMITENTES!#REF!,D4,COMITENTES!$H:$H),IF(H4="fora",0%,F4/QUÓRUM!$H$4)) -> #DIV/0! | H4: =IF(OR(MID(D4,7,2)="10",MID(D4,7,2)="20",MID(D4,7,2)="68"),"PREENCHER NA PRÓXIMA ABA","")
G5: =IF(OR(MID(D5,7,2)="10",MID(D5,7,2)="20",MID(D5,7,2)="68"),SUMIF(COMITENTES!#REF!,D5,COMITENTES!$H:$H),IF(H5="fora",0%,F5/QUÓRUM!$H$4)) -> #DIV/0! | H5: =IF(OR(MID(D5,7,2)="10",MID(D5,7,2)="20",MID(D5,7,2)="68"),"PREENCHER NA PRÓXIMA ABA","")
G6: =IF(OR(MID(D6,7,2)="10",MID(D6,7,2)="20",MID(D6,7,2)="68"),SUMIF(COMITENTES!#REF!,D6,COMITENTES!$H:$H),IF(H6="fora",0%,F6/QUÓRUM!$H$4)) -> #DIV/0! | H6: =IF(OR(MID(D6,7,2)="10",MID(D6,7,2)="20",MID(D6,7,2)="68"),"PREENCHER NA PRÓXIMA ABA","")
G7: =IF(OR(MID(D7,7,2)="10",MID(D7,7,2)="20",MID(D7,7,2)="68"),SUMIF(COMITENTES!#REF!,D7,COMITENTES!$H:$H),IF(H7="fora",0%,F7/QUÓRUM!$H$4)) -> #DIV/0! | H7: =IF(OR(MID(D7,7,2)="10",MID(D7,7,2)="20",MID(D7,7,2)="68"),"PREENCHER NA PRÓXIMA ABA","")
G8: =IF(OR(MID(D8,7,2)="10",MID(D8,7,2)="20",MID(D8,7,2)="68"),SUMIF(COMITENTES!#REF!,D8,COMITENTES!$H:$H),IF(H8="fora",0%,F8/QUÓRUM!$H$4)) -> #DIV/0! | H8: =IF(OR(MID(D8,7,2)="10",MID(D8,7,2)="20",MID(D8,7,2)="68"),"PREENCHER NA PRÓXIMA ABA","")
G9: =IF(OR(MID(D9,7,2)="10",MID(D9,7,2)="20",MID(D9,7,2)="68"),SUMIF(COMITENTES!#REF!,D9,COMITENTES!$H:$H),IF(H9="fora",0%,F9/QUÓRUM!$H$4)) -> #DIV/0! | H9: =IF(OR(MID(D9,7,2)="10",MID(D9,7,2)="20",MID(D9,7,2)="68"),"PREENCHER NA PRÓXIMA ABA","")
G10: =IF(OR(MID(D10,7,2)="10",MID(D10,7,2)="20",MID(D10,7,2)="68"),SUMIF(COMITENTES!#REF!,D10,COMITENTES!$H:$H),IF(H10="fora",0%,F10/QUÓRUM!$H$4)) -> #DIV/0! | H10: =IF(OR(MID(D10,7,2)="10",MID(D10,7,2)="20",MID(D10,7,2)="68"),"PREENCHER NA PRÓXIMA ABA","")
G11: =IF(OR(MID(D11,7,2)="10",MID(D11,7,2)="20",MID(D11,7,2)="68"),SUMIF(COMITENTES!#REF!,D11,COMITENTES!$H:$H),IF(H11="fora",0%,F11/QUÓRUM!$H$4)) -> #DIV/0! | H11: =IF(OR(MID(D11,7,2)="10",MID(D11,7,2)="20",MID(D11,7,2)="68"),"PREENCHER NA PRÓXIMA ABA","")
G12: =IF(OR(MID(D12,7,2)="10",MID(D12,7,2)="20",MID(D12,7,2)="68"),SUMIF(COMITENTES!#REF!,D12,COMITENTES!$H:$H),IF(H12="fora",0%,F12/QUÓRUM!$H$4)) -> #DIV/0! | H12: =IF(OR(MID(D12,7,2)="10",MID(D12,7,2)="20",MID(D12,7,2)="68"),"PREENCHER NA PRÓXIMA ABA","")
G13: =IF(OR(MID(D13,7,2)="10",MID(D13,7,2)="20",MID(D13,7,2)="68"),SUMIF(COMITENTES!#REF!,D13,COMITENTES!$H:$H),IF(H13="fora",0%,F13/QUÓRUM!$H$4)) -> #DIV/0! | H13: =IF(OR(MID(D13,7,2)="10",MID(D13,7,2)="20",MID(D13,7,2)="68"),"PREENCHER NA PRÓXIMA ABA","")
... G208: =IF(OR(MID(D208,7,2)="10",MID(D208,7,2)="20",MID(D208,7,2)="68"),SUMIF(COMITENTES!#REF!,D208,COMITENTES!$H:$H),IF(H208="fora",0%,F208/QUÓRUM!$H$4)) -> #DIV/0! | H208: =IF(OR(MID(D208,7,2)="10",MID(D208,7,2)="20",MID(D208,7,2)="68"),"PREENCHER NA PRÓXIMA ABA","")
G209: =IF(OR(MID(D209,7,2)="10",MID(D209,7,2)="20",MID(D209,7,2)="68"),SUMIF(COMITENTES!#REF!,D209,COMITENTES!$H:$H),IF(H209="fora",0%,F209/QUÓRUM!$H$4)) -> #DIV/0!
G210: =IF(OR(MID(D210,7,2)="10",MID(D210,7,2)="20",MID(D210,7,2)="68"),SUMIF(COMITENTES!#REF!,D210,COMITENTES!$H:$H),IF(H210="fora",0%,F210/QUÓRUM!$H$4)) -> #DIV/0!
G211: =IF(OR(MID(D211,7,2)="10",MID(D211,7,2)="20",MID(D211,7,2)="68"),SUMIF(COMITENTES!#REF!,D211,COMITENTES!$H:$H),IF(H211="fora",0%,F211/QUÓRUM!$H$4)) -> #DIV/0!
G212: =IF(OR(MID(D212,7,2)="10",MID(D212,7,2)="20",MID(D212,7,2)="68"),SUMIF(COMITENTES!#REF!,D212,COMITENTES!$H:$H),IF(H212="fora",0%,F212/QUÓRUM!$H$4)) -> #DIV/0!
G213: =IF(OR(MID(D213,7,2)="10",MID(D213,7,2)="20",MID(D213,7,2)="68"),SUMIF(COMITENTES!#REF!,D213,COMITENTES!$H:$H),IF(H213="fora",0%,F213/QUÓRUM!$H$4)) -> #DIV/0!
G214: =IF(OR(MID(D214,7,2)="10",MID(D214,7,2)="20",MID(D214,7,2)="68"),SUMIF(COMITENTES!#REF!,D214,COMITENTES!$H:$H),IF(H214="fora",0%,F214/QUÓRUM!$H$4)) -> #DIV/0!
G215: =IF(OR(MID(D215,7,2)="10",MID(D215,7,2)="20",MID(D215,7,2)="68"),SUMIF(COMITENTES!#REF!,D215,COMITENTES!$H:$H),IF(H215="fora",0%,F215/QUÓRUM!$H$4)) -> #DIV/0!
G216: =IF(OR(MID(D216,7,2)="10",MID(D216,7,2)="20",MID(D216,7,2)="68"),SUMIF(COMITENTES!#REF!,D216,COMITENTES!$H:$H),IF(H216="fora",0%,F216/QUÓRUM!$H$4)) -> #DIV/0!
G217: =IF(OR(MID(D217,7,2)="10",MID(D217,7,2)="20",MID(D217,7,2)="68"),SUMIF(COMITENTES!#REF!,D217,COMITENTES!$H:$H),IF(H217="fora",0%,F217/QUÓRUM!$H$4)) -> #DIV/0!
G218: =IF(OR(MID(D218,7,2)="10",MID(D218,7,2)="20",MID(D218,7,2)="68"),SUMIF(COMITENTES!#REF!,D218,COMITENTES!$H:$H),IF(H218="fora",0%,F218/QUÓRUM!$H$4)) -> #DIV/0!
G219: =IF(OR(MID(D219,7,2)="10",MID(D219,7,2)="20",MID(D219,7,2)="68"),SUMIF(COMITENTES!#REF!,D219,COMITENTES!$H:$H),IF(H219="fora",0%,F219/QUÓRUM!$H$4)) -> #DIV/0!
G220: =IF(OR(MID(D220,7,2)="10",MID(D220,7,2)="20",MID(D220,7,2)="68"),SUMIF(COMITENTES!#REF!,D220,COMITENTES!$H:$H),IF(H220="fora",0%,F220/QUÓRUM!$H$4)) -> #DIV/0!
... G361: =IF(OR(MID(D361,7,2)="10",MID(D361,7,2)="20",MID(D361,7,2)="68"),SUMIF(COMITENTES!#REF!,D361,COMITENTES!$H:$H),IF(H361="fora",0%,F361/QUÓRUM!$H$4)) -> #DIV/0!

Sheet COMITENTES
A1: Agente Custodia | B1: Documento Participante | C1: Gestão | D1: Nome comitente | E1: CPF/CNPJ Comitente | F1: Tipo Pessoa | G1: Quantidade | H1: % | I1: Presença (OK ou FORA) | J1: Documentos | K1: Representante | L1: Item1 | M1: Item 2 | N1: Item 3 | O1: Item 4 | P1: Item 5 | Q1: Séries | R1: PU | S1: Posição $ | T1: Posição %
H2: =IF(I2="fora",0%,G2/QUÓRUM!$C$6) -> #DIV/0! | Q2: única
H3: =IF(I3="fora",0%,G3/QUÓRUM!$C$6) -> #DIV/0! | Q3: única
H4: =IF(I4="fora",0%,G4/QUÓRUM!$C$6) -> #DIV/0!
H5: =IF(I5="fora",0%,G5/QUÓRUM!$C$6) -> #DIV/0!
H6: =IF(I6="fora",0%,G6/QUÓRUM!$C$6) -> #DIV/0!
H7: =IF(I7="fora",0%,G7/QUÓRUM!$C$6) -> #DIV/0!
H8: =IF(I8="fora",0%,G8/QUÓRUM!$C$6) -> #DIV/0!
H9: =IF(I9="fora",0%,G9/QUÓRUM!$C$6) -> #DIV/0!
H10: =IF(I10="fora",0%,G10/QUÓRUM!$C$6) -> #DIV/0!
H11: =IF(I11="fora",0%,G11/QUÓRUM!$C$6) -> #DIV/0!
H12: =IF(I12="fora",0%,G12/QUÓRUM!$C$6) -> #DIV/0!
H13: =IF(I13="fora",0%,G13/QUÓRUM!$C$6) -> #DIV/0!
H14: =IF(I14="fora",0%,G14/QUÓRUM!$C$6) -> #DIV/0!
H15: =IF(I15="fora",0%,G15/QUÓRUM!$C$6) -> #DIV/0!
... H35: =IF(I35="fora",0%,G35/QUÓRUM!$C$6) -> #DIV/0!
H36: =IF(I36="fora",0%,G36/QUÓRUM!$C$6) -> #DIV/0! | S36: =R36*G36 -> 0 | T36: =IF(I36="fora",0%,S36/QUÓRUM!$M$7) -> #DIV/0!
H37: =IF(I37="fora",0%,G37/QUÓRUM!$C$6) -> #DIV/0!
H38: =IF(I38="fora",0%,G38/QUÓRUM!$C$6) -> #DIV/0!
H39: =IF(I39="fora",0%,G39/QUÓRUM!$C$6) -> #DIV/0!
H40: =IF(I40="fora",0%,G40/QUÓRUM!$C$6) -> #DIV/0!
H41: =IF(I41="fora",0%,G41/QUÓRUM!$C$6) -> #DIV/0!
H42: =IF(I42="fora",0%,G42/QUÓRUM!$C$6) -> #DIV/0!
H43: =IF(I43="fora",0%,G43/QUÓRUM!$C$6) -> #DIV/0!
H44: =IF(I44="fora",0%,G44/QUÓRUM!$C$6) -> #DIV/0!
H45: =IF(I45="fora",0%,G45/QUÓRUM!$C$6) -> #DIV/0!
H46: =IF(I46="fora",0%,G46/QUÓRUM!$C$6) -> #DIV/0!
H47: =IF(I47="fora",0%,G47/QUÓRUM!$C$6) -> #DIV/0!
H48: =IF(I48="fora",0%,G48/QUÓRUM!$C$6) -> #DIV/0!
... H95: =IF(I95="fora",0%,G95/QUÓRUM!$C$6) -> #DIV/0!
H96: =IF(I96="fora",0%,G96/QUÓRUM!$C$6) -> #DIV/0! | S96: =R96*G96 -> 0 | T96: =IF(I96="fora",0%,S96/QUÓRUM!$M$7) -> #DIV/0!
H97: =IF(I97="fora",0%,G97/QUÓRUM!$C$6) -> #DIV/0! | S97: =R97*G97 -> 0 | T97: =IF(I97="fora",0%,S97/QUÓRUM!$M$7) -> #DIV/0!
H98: =IF(I98="fora",0%,G98/QUÓRUM!$C$6) -> #DIV/0!
H99: =IF(I99="fora",0%,G99/QUÓRUM!$C$6) -> #DIV/0!
H100: =IF(I100="fora",0%,G100/QUÓRUM!$C$6) -> #DIV/0! | S100: =R100*G100 -> 0 | T100: =IF(I100="fora",0%,S100/QUÓRUM!$M$7) -> #DIV/0!
H101: =IF(I101="fora",0%,G101/QUÓRUM!$C$6) -> #DIV/0!
H102: =IF(I102="fora",0%,G102/QUÓRUM!$C$6) -> #DIV/0!
H103: =IF(I103="fora",0%,G103/QUÓRUM!$C$6) -> #DIV/0!
H104: =IF(I104="fora",0%,G104/QUÓRUM!$C$6) -> #DIV/0!
H105: =IF(I105="fora",0%,G105/QUÓRUM!$C$6) -> #DIV/0!
...

Sheet QUÓRUM
B1: Quantidade Circulação | G1: Quantidade Presentes | L1: Saldo Devedor
B3: DATA DE EMISSÃO DA LISTAGEM | G3: DATA DE EMISSÃO DA LISTAGEM | L3: DATA DE EMISSÃO DA LISTAGEM
B4: TOTAL | C4: =SUM(COMITENTES!$G:$G) -> 0 | G4: TOTAL | H4: =SUM(COMITENTES!$G:$G) -> 0 | L4: TOTAL | M4: =SUM(COMITENTES!S:S) -> 0
B5: FORA DE CIRCULAÇÃO | C5: =SUMIF(COMITENTES!$I:$I,"FORA",COMITENTES!$G:$G) -> 0 | D5: =C5/C4 -> #DIV/0! | G5: FORA DE CIRCULAÇÃO | H5: =SUMIF(PARTICIPANTES!$H:$H,"FORA",PARTICIPANTES!$F:$F)+SUMIF(COMITENTES!$I:$I,"FORA",COMITENTES!$G:$G) -> 0 | I5: =H5/H4 -> #DIV/0! | L5: FORA DE CIRCULAÇÃO | M5: =SUMIF(COMITENTES!$I:$I,"FORA",COMITENTES!$S:$S) -> 0 | N5: =M5/M4 -> #DIV/0!
B6: EM CIRCULAÇÃO | C6: =C4-C5 -> 0 | G6: EM CIRCULAÇÃO | H6: =H4-H5 -> 0 | L6: EM CIRCULAÇÃO | M6: =M4-M5 -> 0
B7: QUÓRUM | C7: =SUMIF(COMITENTES!$I:$I,"OK",COMITENTES!$G:$G) -> 0 | D7: =C7/C6 -> #DIV/0! | G7: QUÓRUM | H7: =SUMIF(COMITENTES!$I:$I,"OK",COMITENTES!$G:$G) -> 0 | L7: QUÓRUM | M7: =SUMIF(COMITENTES!$I:$I,"OK",COMITENTES!$S:$S) -> 0 | N7: =M7/M4 -> #DIV/0!
B9: Item 1 | D9: =$C$6-C13-C14 -> 0 | E9: Em caso de Abstenção | G9: Item 1 | I9: =H7-H13-H14 -> 0 | J9: Em caso de Abstenção | L9: Item 1 | M9: =SUM(M10:M14) -> 0 | N9: =$M$6-M13-M14 -> 0 | O9: Em caso de Abstenção
B10: SIM | C10: =SUMIF(COMITENTES!$L:$L,QUÓRUM!B10,COMITENTES!$G:$G) -> 0 | D10: =C10/$C$6 -> #DIV/0! | E10: =C10/$D$9 -> #DIV/0! | G10: SIM | H10: =SUMIF(COMITENTES!$L:$L,QUÓRUM!G10,COMITENTES!$G:$G) -> 0 | I10: =H10/$H$7 -> #DIV/0! | J10: =H10/$I$9 -> #DIV/0! | L10: SIM | M10: =SUMIF(COMITENTES!$L:$L,QUÓRUM!L10,COMITENTES!$S:$S) -> 0 | N10: =M10/$M$6 -> #DIV/0! | O10: =M10/$N$9 -> #DIV/0!
B11: NÃO | C11: =SUMIF(COMITENTES!$L:$L,QUÓRUM!B11,COMITENTES!$G:$G) -> 0 | D11: =C11/$C$6 -> #DIV/0! | E11: =C11/$D$9 -> #DIV/0! | G11: NÃO | H11: =SUMIF(COMITENTES!$L:$L,QUÓRUM!G11,COMITENTES!$G:$G) -> 0 | I11: =H11/$H$7 -> #DIV/0! | J11: =H11/$I$9 -> #DIV/0! | L11: NÃO | M11: =SUMIF(COMITENTES!$L:$L,QUÓRUM!L11,COMITENTES!$S:$S) -> 0 | N11: =M11/$M$6 -> #DIV/0! | O11: =M11/$N$9 -> #DIV/0!
B12: SUSPENSÃO | C12: =SUMIF(COMITENTES!$L:$L,QUÓRUM!B12,COMITENTES!$G:$G) -> 0 | D12: =C12/$C$6 -> #DIV/0! | E12: =C12/$D$9 -> #DIV/0! | G12: SUSPENSÃO | H12: =SUMIF(COMITENTES!$L:$L,QUÓRUM!G12,COMITENTES!$G:$G) -> 0 | I12: =H12/$H$7 -> #DIV/0! | J12: =H12/$I$9 -> #DIV/0! | L12: SUSPENSÃO | M12: =SUMIF(COMITENTES!$L:$L,QUÓRUM!L12,COMITENTES!$S:$S) -> 0 | N12: =M12/$M$6 -> #DIV/0! | O12: =M12/$N$9 -> #DIV/0!
B13: ABSTENÇÃO | C13: =SUMIF(COMITENTES!$L:$L,QUÓRUM!B13,COMITENTES!$G:$G) -> 0 | D13: =C13/$C$6 -> #DIV/0! | G13: ABSTENÇÃO | H13: =SUMIF(COMITENTES!$L:$L,QUÓRUM!G13,COMITENTES!$G:$G) -> 0 | I13: =H13/$H$7 -> #DIV/0! | L13: ABSTENÇÃO | M13: =SUMIF(COMITENTES!$L:$L,QUÓRUM!L13,COMITENTES!$S:$S) -> 0 | N13: =M13/$M$6 -> #DIV/0! | O13: =M13/$N$9 -> #DIV/0!
B14: ABERTO | C14: =SUMIF(COMITENTES!$L:$L,QUÓRUM!B14,COMITENTES!$G:$G) -> 0 | D14: =C14/$C$6 -> #DIV/0! | G14: ABERTO | H14: =SUMIF(COMITENTES!$L:$L,QUÓRUM!G14,COMITENTES!$G:$G) -> 0 | I14: =H14/$H$7 -> #DIV/0! | L14: ABERTO | M14: =SUMIF(COMITENTES!$L:$L,QUÓRUM!L14,COMITENTES!$S:$S) -> 0 | N14: =M14/$M$6 -> #DIV/0! | O14: =M14/$N$9 -> #DIV/0!
B16: Item 2 | D16: =$C$6-C20-C21 -> 0 | E16: Em caso de Abstenção | G16: Item 2 | I16: =H7-H20-H21 -> 0 | J16: Em caso de Abstenção | L16: Item 2 | M16: =SUM(M17:M21) -> 0 | N16: =$M$6-M20-M21 -> 0 | O16: Em caso de Abstenção
B17: SIM | C17: =SUMIF(COMITENTES!$M:$M,QUÓRUM!B17,COMITENTES!$G:$G) -> 0 | D17: =C17/$C$6 -> #DIV/0! | E17: =C17/$D$16 -> #DIV/0! | G17: SIM | H17: =SUMIF(COMITENTES!$M:$M,QUÓRUM!G17,COMITENTES!$G:$G) -> 0 | I17: =H17/$H$7 -> #DIV/0! | J17: =H17/$I$16 -> #DIV/0! | L17: SIM | M17: =SUMIF(COMITENTES!$M:$M,QUÓRUM!L17,COMITENTES!$S:$S) -> 0 | N17: =M17/$M$6 -> #DIV/0! | O17: =M17/$N$16 -> #DIV/0!
B18: NÃO | C18: =SUMIF(COMITENTES!$M:$M,QUÓRUM!B18,COMITENTES!$G:$G) -> 0 | D18: =C18/$C$6 -> #DIV/0! | E18: =C18/$D$16 -> #DIV/0! | G18: NÃO | H18: =SUMIF(COMITENTES!$M:$M,QUÓRUM!G18,COMITENTES!$G:$G) -> 0 | I18: =H18/$H$7 -> #DIV/0! | J18: =H18/$I$16 -> #DIV/0! | L18: NÃO | M18: =SUMIF(COMITENTES!$M:$M,QUÓRUM!L18,COMITENTES!$S:$S) -> 0 | N18: =M18/$M$6 -> #DIV/0! | O18: =M18/$N$16 -> #DIV/0!
B19: SUSPENSÃO | C19: =SUMIF(COMITENTES!$M:$M,QUÓRUM!B19,COMITENTES!$G:$G) -> 0 | D19: =C19/$C$6 -> #DIV/0! | E19: =C19/$D$16 -> #DIV/0! | G19: SUSPENSÃO | H19: =SUMIF(COMITENTES!$M:$M,QUÓRUM!G19,COMITENTES!$G:$G) -> 0 | I19: =H19/$H$7 -> #DIV/0! | J19: =H19/$I$16 -> #DIV/0! | L19: SUSPENSÃO | M19: =SUMIF(COMITENTES!$M:$M,QUÓRUM!L19,COMITENTES!$S:$S) -> 0 | N19: =M19/$M$6 -> #DIV/0! | O19: =M19/$N$16 -> #DIV/0!
B20: ABSTENÇÃO | C20: =SUMIF(COMITENTES!$M:$M,QUÓRUM!B20,COMITENTES!$G:$G) -> 0 | D20: =C20/$C$6 -> #DIV/0! | G20: abstenção | H20: =SUMIF(COMITENTES!$M:$M,QUÓRUM!G20,COMITENTES!$G:$G) -> 0 | I20: =H20/$H$7 -> #DIV/0! | L20: ABSTENÇÃO | M20: =SUMIF(COMITENTES!$M:$M,QUÓRUM!L20,COMITENTES!$S:$S) -> 0 | N20: =M20/$M$6 -> #DIV/0! | O20: =M20/$N$16 -> #DIV/0!
B21: ABERTO | C21: =SUMIF(COMITENTES!$M:$M,QUÓRUM!B21,COMITENTES!$G:$G) -> 0 | D21: =C21/$C$6 -> #DIV/0! | G21: ABERTO | H21: =SUMIF(COMITENTES!$M:$M,QUÓRUM!G21,COMITENTES!$G:$G) -> 0 | I21: =H21/$H$7 -> #DIV/0! | L21: ABERTO | M21: =SUMIF(COMITENTES!$M:$M,QUÓRUM!L21,COMITENTES!$S:$S) -> 0 | N21: =M21/$M$6 -> #DIV/0! | O21: =M21/$N$16 -> #DIV/0!
B23: Item 3 | D23: =$C$6-C27-C28 -> 0 | E23: Em caso de Abstenção | G23: Item 3 | I23: =H7-H27-H28 -> 0 | J23: Em caso de Abstenção | L23: Item 3 | M23: =SUM(M24:M28) -> 0 | N23: =$M$6-M27-M28 -> 0 | O23: Em caso de Abstenção
B24: SIM | C24: =SUMIF(COMITENTES!$N:$N,QUÓRUM!B24,COMITENTES!$G:$G) -> 0 | D24: =C24/$C$6 -> #DIV/0! | E24: =C24/$D$23 -> #DIV/0! | G24: SIM | H24: =SUMIF(COMITENTES!$N:$N,QUÓRUM!G24,COMITENTES!$G:$G) -> 0 | I24: =H24/$H$7 -> #DIV/0! | J24: =H24/$I$23 -> #DIV/0! | L24: SIM | M24: =SUMIF(COMITENTES!$N:$N,QUÓRUM!L24,COMITENTES!$S:$S) -> 0 | N24: =M24/$M$6 -> #DIV/0! | O24: =M24/$N$23 -> #DIV/0!
B25: NÃO | C25: =SUMIF(COMITENTES!$N:$N,QUÓRUM!B25,COMITENTES!$G:$G) -> 0 | D25: =C25/$C$6 -> #DIV/0! | E25: =C25/$D$23 -> #DIV/0! | G25: NÃO | H25: =SUMIF(COMITENTES!$N:$N,QUÓRUM!G25,COMITENTES!$G:$G) -> 0 | I25: =H25/$H$7 -> #DIV/0! | J25: =H25/$I$23 -> #DIV/0! | L25: NÃO | M25: =SUMIF(COMITENTES!$N:$N,QUÓRUM!L25,COMITENTES!$S:$S) -> 0 | N25: =M25/$M$6 -> #DIV/0! | O25: =M25/$N$23 -> #DIV/0!
B26: SUSPENSÃO | C26: =SUMIF(COMITENTES!$N:$N,QUÓRUM!B26,COMITENTES!$G:$G) -> 0 | D26: =C26/$C$6 -> #DIV/0! | E26: =C26/$D$23 -> #DIV/0! | G26: SUSPENSÃO | H26: =SUMIF(COMITENTES!$N:$N,QUÓRUM!G26,COMITENTES!$G:$G) -> 0 | I26: =H26/$H$7 -> #DIV/0! | J26: =H26/$I$23 -> #DIV/0! | L26: SUSPENSÃO | M26: =SUMIF(COMITENTES!$N:$N,QUÓRUM!L26,COMITENTES!$S:$S) -> 0 | N26: =M26/$M$6 -> #DIV/0! | O26: =M26/$N$23 -> #DIV/0!
B27: ABSTENÇÃO | C27: =SUMIF(COMITENTES!$N:$N,QUÓRUM!B27,COMITENTES!$G:$G) -> 0 | D27: =C27/$C$6 -> #DIV/0! | G27: ABSTENÇÃO | H27: =SUMIF(COMITENTES!$N:$N,QUÓRUM!G27,COMITENTES!$G:$G) -> 0 | I27: =H27/$H$7 -> #DIV/0! | L27: ABSTENÇÃO | M27: =SUMIF(COMITENTES!$N:$N,QUÓRUM!L27,COMITENTES!$S:$S) -> 0 | N27: =M27/$M$6 -> #DIV/0! | O27: =M27/$N$23 -> #DIV/0!
B28: ABERTO | C28: =SUMIF(COMITENTES!$N:$N,QUÓRUM!B28,COMITENTES!$G:$G) -> 0 | D28: =C28/$C$6 -> #DIV/0! | G28: ABERTO | H28: =SUMIF(COMITENTES!$N:$N,QUÓRUM!G28,COMITENTES!$G:$G) -> 0 | I28: =H28/$H$7 -> #DIV/0! | L28: ABERTO | M28: =SUMIF(COMITENTES!$N:$N,QUÓRUM!L28,COMITENTES!$S:$S) -> 0 | N28: =M28/$M$6 -> #DIV/0! | O28: =M28/$N$23 -> #DIV/0!
B30: Item 4 | D30: =$C$6-C34-C35 -> 0 | E30: Em caso de Abstenção | G30: Item 4 | I30: =H7-H34-H35 -> 0 | J30: Em caso de Abstenção | L30: Item 4 | M30: =SUM(M31:M35) -> 0 | N30: =$M$6-M34-M35 -> 0 | O30: Em caso de Abstenção
B31: SIM | C31: =SUMIF(COMITENTES!$O:$O,QUÓRUM!B31,COMITENTES!$G:$G) -> 0 | D31: =C31/$C$6 -> #DIV/0! | E31: =C31/$D$30 -> #DIV/0! | G31: SIM | H31: =SUMIF(COMITENTES!$O:$O,QUÓRUM!G31,COMITENTES!$G:$G) -> 0 | I31: =H31/$H$7 -> #DIV/0! | J31: =H31/$I$30 -> #DIV/0! | L31: SIM | M31: =SUMIF(COMITENTES!$O:$O,QUÓRUM!L31,COMITENTES!$S:$S) -> 0 | N31: =M31/$M$6 -> #DIV/0! | O31: =M31/$N$23 -> #DIV/0!
B32: NÃO | C32: =SUMIF(COMITENTES!$O:$O,QUÓRUM!B32,COMITENTES!$G:$G) -> 0 | D32: =C32/$C$6 -> #DIV/0! | E32: =C32/$D$30 -> #DIV/0! | G32: NÃO | H32: =SUMIF(COMITENTES!$O:$O,QUÓRUM!G32,COMITENTES!$G:$G) -> 0 | I32: =H32/$H$7 -> #DIV/0! | J32: =H32/$I$30 -> #DIV/0! | L32: NÃO | M32: =SUMIF(COMITENTES!$O:$O,QUÓRUM!L32,COMITENTES!$S:$S) -> 0 | N32: =M32/$M$6 -> #DIV/0! | O32: =M32/$N$23 -> #DIV/0!
B33: SUSPENSÃO | C33: =SUMIF(COMITENTES!$O:$O,QUÓRUM!B33,COMITENTES!$G:$G) -> 0 | D33: =C33/$C$6 -> #DIV/0! | E33: =C33/$D$30 -> #DIV/0! | G33: SUSPENSÃO | H33: =SUMIF(COMITENTES!$O:$O,QUÓRUM!G33,COMITENTES!$G:$G) -> 0 | I33: =H33/$H$7 -> #DIV/0! | J33: =H33/$I$30 -> #DIV/0! | L33: SUSPENSÃO | M33: =SUMIF(COMITENTES!$O:$O,QUÓRUM!L33,COMITENTES!$S:$S) -> 0 | N33: =M33/$M$6 -> #DIV/0! | O33: =M33/$N$23 -> #DIV/0!
B34: ABSTENÇÃO | C34: =SUMIF(COMITENTES!$O:$O,QUÓRUM!B34,COMITENTES!$G:$G) -> 0 | D34: =C34/$C$6 -> #DIV/0! | G34: ABSTENÇÃO | H34: =SUMIF(COMITENTES!$O:$O,QUÓRUM!G34,COMITENTES!$G:$G) -> 0 | I34: =H34/$H$7 -> #DIV/0! | L34: ABSTENÇÃO | M34: =SUMIF(COMITENTES!$O:$O,QUÓRUM!L34,COMITENTES!$S:$S) -> 0 | N34: =M34/$M$6 -> #DIV/0! | O34: =M34/$N$23 -> #DIV/0!
B35: ABERTO | C35: =SUMIF(COMITENTES!$O:$O,QUÓRUM!B35,COMITENTES!$G:$G) -> 0 | D35: =C35/$C$6 -> #DIV/0! | G35: ABERTO | H35: =SUMIF(COMITENTES!$O:$O,QUÓRUM!G35,COMITENTES!$G:$G) -> 0 | I35: =H35/$H$7 -> #DIV/0! | L35: ABERTO | M35: =SUMIF(COMITENTES!$O:$O,QUÓRUM!L35,COMITENTES!$S:$S) -> 0 | N35: =M35/$M$6 -> #DIV/0! | O35: =M35/$N$23 -> #DIV/0!
B37: Item 5 | D37: =$C$6-C41-C42 -> 0 | E37: Em caso de Abstenção | G37: Item 5 | I37: =H7-H41-H42 -> 0 | J37: Em caso de Abstenção | L37: Item 5 | M37: =SUM(M38:M42) -> 0 | N37: =$M$6-M41-M42 -> 0 | O37: Em caso de Abstenção
B38: SIM | C38: =SUMIF(COMITENTES!$P:$P,QUÓRUM!B38,COMITENTES!$G:$G) -> 0 | D38: =C38/$C$6 -> #DIV/0! | E38: =C38/$D$37 -> #DIV/0! | G38: SIM | H38: =SUMIF(COMITENTES!$P:$P,QUÓRUM!G38,COMITENTES!$G:$G) -> 0 | I38: =H38/$H$7 -> #DIV/0! | J38: =H38/$I$37 -> #DIV/0! | L38: SIM | M38: =SUMIF(COMITENTES!$P:$P,QUÓRUM!L38,COMITENTES!$S:$S) -> 0 | N38: =M38/$M$6 -> #DIV/0! | O38: =M38/$N$23 -> #DIV/0!
B39: NÃO | C39: =SUMIF(COMITENTES!$P:$P,QUÓRUM!B39,COMITENTES!$G:$G) -> 0 | D39: =C39/$C$6 -> #DIV/0! | E39: =C39/$D$37 -> #DIV/0! | G39: NÃO | H39: =SUMIF(COMITENTES!$P:$P,QUÓRUM!G39,COMITENTES!$G:$G) -> 0 | I39: =H39/$H$7 -> #DIV/0! | J39: =H39/$I$9 -> #DIV/0! | L39: NÃO | M39: =SUMIF(COMITENTES!$P:$P,QUÓRUM!L39,COMITENTES!$S:$S) -> 0 | N39: =M39/$M$6 -> #DIV/0! | O39: =M39/$N$23 -> #DIV/0!
B40: SUSPENSÃO | C40: =SUMIF(COMITENTES!$P:$P,QUÓRUM!B40,COMITENTES!$G:$G) -> 0 | D40: =C40/$C$6 -> #DIV/0! | E40: =C40/$D$37 -> #DIV/0! | G40: SUSPENSÃO | H40: =SUMIF(COMITENTES!$P:$P,QUÓRUM!G40,COMITENTES!$G:$G) -> 0 | I40: =H40/$H$7 -> #DIV/0! | J40: =H40/$I$9 -> #DIV/0! | L40: SUSPENSÃO | M40: =SUMIF(COMITENTES!$P:$P,QUÓRUM!L40,COMITENTES!$S:$S) -> 0 | N40: =M40/$M$6 -> #DIV/0! | O40: =M40/$N$23 -> #DIV/0!
B41: ABSTENÇÃO | C41: =SUMIF(COMITENTES!$P:$P,QUÓRUM!B41,COMITENTES!$G:$G) -> 0 | D41: =C41/$C$6 -> #DIV/0! | G41: ABSTENÇÃO | H41: =SUMIF(COMITENTES!$P:$P,QUÓRUM!G41,COMITENTES!$G:$G) -> 0 | I41: =H41/$H$7 -> #DIV/0! | L41: ABSTENÇÃO | M41: =SUMIF(COMITENTES!$P:$P,QUÓRUM!L41,COMITENTES!$S:$S) -> 0 | N41: =M41/$M$6 -> #DIV/0! | O41: =M41/$N$23 -> #DIV/0!
B42: ABERTO | C42: =SUMIF(COMITENTES!$P:$P,QUÓRUM!B42,COMITENTES!$G:$G) -> 0 | D42: =C42/$C$6 -> #DIV/0! | G42: ABERTO | H42: =SUMIF(COMITENTES!$P:$P,QUÓRUM!G42,COMITENTES!$G:$G) -> 0 | I42: =H42/$H$7 -> #DIV/0! | L42: ABERTO | M42: =SUMIF(COMITENTES!$P:$P,QUÓRUM!L42,COMITENTES!$S:$S) -> 0 | N42: =M42/$M$6 -> #DIV/0! | O42: =M42/$N$23 -> #DIV/0!
